2024-09-22 16:54:01,496 - __main__             - INFO    : Starting remote job on gegi-acad-alma. pid: 1010086
2024-09-22 16:54:02,009 - runner               - INFO    : Initializing RUN phase
2024-09-22 16:54:02,009 - runner               - INFO    : Run id: 3
2024-09-22 16:54:02,009 - runner               - INFO    : Setting up environment
2024-09-22 16:54:03,883 - RUN                  - INFO    : Initializing run phase
2024-09-22 16:54:03,897 - RUN                  - INFO    : Starting run phase
2024-09-22 16:54:03,898 - RUN                  - INFO    : Debug log file: /home/lacp3102/APP1/UdeS_S8_APP1/formatif/gei816-formatif-amorce/verif/regression_area/example_session.lacp3102.24_09_22_16_53_45_0377/chain_0/debug_logs/vm_remote_job_c7f40870-873e-4709-8deb-12cd1141dfb5.log
2024-09-22 16:54:03,898 - RUN                  - INFO    : Running run no. 3
2024-09-22 16:54:03,898 - RUN                  - INFO    : Timeout is set to 900 seconds
2024-09-22 16:54:03,898 - RUN                  - INFO    : Executing run script: "/home/lacp3102/APP1/UdeS_S8_APP1/formatif/gei816-formatif-amorce/verif/scripts/do_vmanager_runsim.tcsh"
2024-09-22 16:54:03,910 - RUN                  - ERROR   : vm_runner: *E,VMRFEXEC: '/home/lacp3102/APP1/UdeS_S8_APP1/formatif/gei816-formatif-amorce/verif/scripts/do_vmanager_runsim.tcsh' failed to execute!
2024-09-22 16:54:03,910 - RUN                  - ERROR   : run 3 script '/home/lacp3102/APP1/UdeS_S8_APP1/formatif/gei816-formatif-amorce/verif/scripts/do_vmanager_runsim.tcsh' exited with exit code 126
2024-09-22 16:54:03,912 - phases.phase         - INFO    : Traceback (most recent call last):
  File "/mnt/opt/cmc/tools/cadence/VMANAGER23.03.002_lnx86/tools/vmgr/jobs_manager/python/../../runner/python/phases/phase.py", line 105, in start
    raise e
  File "/mnt/opt/cmc/tools/cadence/VMANAGER23.03.002_lnx86/tools/vmgr/jobs_manager/python/../../runner/python/phases/phase.py", line 98, in start
    self._run()
  File "/mnt/opt/cmc/tools/cadence/VMANAGER23.03.002_lnx86/tools/vmgr/jobs_manager/python/../../runner/python/phases/run_phase.py", line 54, in _run
    self._exec_run_script()
  File "/mnt/opt/cmc/tools/cadence/VMANAGER23.03.002_lnx86/tools/vmgr/jobs_manager/python/../../runner/python/utils/time_logger.py", line 17, in wrapped_func
    func_return = func(*args, **kwargs)
  File "/mnt/opt/cmc/tools/cadence/VMANAGER23.03.002_lnx86/tools/vmgr/jobs_manager/python/../../runner/python/phases/run_phase.py", line 262, in _exec_run_script
    raise NonzeroExitException(self._attrs_values.run_script, self.exit_code, 'run {} script'.format(self._context.run_id))
runner_exceptions.NonzeroExitException: run 3 script '/home/lacp3102/APP1/UdeS_S8_APP1/formatif/gei816-formatif-amorce/verif/scripts/do_vmanager_runsim.tcsh' exited with exit code 126

2024-09-22 16:54:03,912 - RUN                  - INFO    : Starting scanning
2024-09-22 16:54:04,745 - RUN                  - INFO    : Run done.
2024-09-22 16:54:04,910 - remote.job_executor  - INFO    : Job finished with exit code: 126
2024-09-22 16:54:04,932 - __main__             - INFO    : Done with exit code 126
